Workbook
Name ASG: #REF!
Name dt1_14125: [1]序列!$B$1:$M$5
Name dtm1_14125: OFFSET([1]!ASG,0,0,1,COUNTA(OFFSET([1]!ASG,0,0,1,COLUMNS([1]!ASG))))

Sheet 资金计划表
A1: 项目资金计划 | M1: 辅助计算列
A2: 版本号： | G2: 日期：20251220
A3: 交叉平台公司：
A4: 项目名称： | B4: 睡个好觉健康管理系统技术服务合同
A5: 一、销售合同列表
A6: 序号 | B6: 合同编号 | C6: 客户 | D6: 销售内容 | E6: 合同名称 | G6: 含税合同额（元） | H6: 税率 | I6: 不含税合同额（元） | J6: 签订日期 | L6: 备注 | M6: 销项税
A7: 1 | B7: 暂无 | C7: 澄迈睡个好觉品牌管理有限公司 | D7: 睡个好觉健康管理系统 | E7: 技术服务合同 | G7: 460000 | H7: 0.06 | I7: =G7/(1+H7) -> 433962.26 | L7: 服务6% | M7: =G7/(1+H7)*H7 -> 26037.736
H8: 0.13 | I8: =G8/(1+H8) -> 0 | L8: 软硬件13% | M8: =G8/(1+H8)*H8 -> 0
H9: 0.09 | I9: =G9/(1+H9) -> 0 | L9: 工程安装9% | M9: =G9/(1+H9)*H9 -> 0
A10: 销售合同额总计： | G10: =SUM(G7:G9) -> 460000 | I10: =SUM(I7:I9) -> 433962.26 | M10: =SUM(M7:M9) -> 26037.736
A11: 二、采购及分包合同列表（包括销售分包、采购分包和交付分包）
A12: 序号 | B12: 合同编号 | C12: 供应商 | D12: 采购内容 | E12: 数量 | F12: 合同名称 | G12: 含税合同额（元） | H12: 税率 | I12: 不含税合同额（元） | J12: 销售金额（元） | K12: 签订日期 | L12: 备注 | M12: 进项税
C13: 陕西百格数据科技有限责任公司 | D13: 睡个好觉健康管理系统 | E13: 1 | F13: 技术服务合同 | G13: 401580 | H13: 0.03 | I13: =G13/(1+H13) -> 389883.5 | L13: 若供应商开具普票，请在H列填写0% | M13: =G13/(1+H13)*H13 -> 11696.505
H14: 0.09 | I14: =G14/(1+H14) -> 0 | L14: 若供应商开具普票，请在H列填写0% | M14: =G14/(1+H14)*H14 -> 0
H15: 0.03 | I15: =G15/(1+H15) -> 0 | L15: 若供应商开具普票，请在H列填写0% | M15: =G15/(1+H15)*H15 -> 0
H16: 0.06 | I16: =G16/(1+H16) -> 0 | L16: 若供应商开具普票，请在H列填写0% | M16: =G16/(1+H16)*H16 -> 0
H17: 0.09 | I17: =G17/(1+H17) -> 0 | L17: 若供应商开具普票，请在H列填写0% | M17: =G17/(1+H17)*H17 -> 0
H18: 0.13 | I18: =G18/(1+H18) -> 0 | L18: 若供应商开具普票，请在H列填写0% | M18: =G18/(1+H18)*H18 -> 0
I19: =G19/(1+H19) -> 0 | L19: 若供应商开具普票，请在H列填写0% | M19: =G19/(1+H19)*H19 -> 0
I20: =G20/(1+H20) -> 0 | L20: 若供应商开具普票，请在H列填写0% | M20: =G20/(1+H20)*H20 -> 0
I21: =G21/(1+H21) -> 0 | L21: 若供应商开具普票，请在H列填写0% | M21: =G21/(1+H21)*H21 -> 0
I22: =G22/(1+H22) -> 0 | L22: 若供应商开具普票，请在H列填写0% | M22: =G22/(1+H22)*H22 -> 0
I23: =G23/(1+H23) -> 0 | L23: 若供应商开具普票，请在H列填写0% | M23: =G23/(1+H23)*H23 -> 0
I24: =G24/(1+H24) -> 0 | L24: 若供应商开具普票，请在H列填写0% | M24: =G24/(1+H24)*H24 -> 0
I25: =G25/(1+H25) -> 0 | L25: 若供应商开具普票，请在H列填写0% | M25: =G25/(1+H25)*H25 -> 0
I26: =G26/(1+H26) -> 0 | L26: 若供应商开具普票，请在H列填写0% | M26: =G26/(1+H26)*H26 -> 0
H27: 0.06 | I27: =G27/(1+H27) -> 0 | L27: 用于填写内部分包模式; G列含税合同额列填交付含税报价，且该金额需等于内部分包交付立项金额； H列税率填写交付侧执行部分对应的销售合同税率。 | M27: 0
C28: 例如：ASG | I28: =G28/(1+H28) -> 0 | L28: 用于填写内部分包模式; G列含税合同额列填交付含税报价，且该金额需等于内部分包交付立项金额； H列税率填写交付侧执行部分对应的销售合同税率。 | M28: 0
C29: 无 | D29: 标书费 | E29: 1 | F29: 无 | I29: =G29/(1+H29) -> 0 | J29: 0元 | L29: 标书购买费用，若不涉及请写0 | M29: =G29/(1+H29)*H29 -> 0
C30: 招标代理机构 | D30: 中标服务费 | E30: 1 | F30: 无 | I30: =G30/(1+H30) -> 0 | J30: 0元 | L30: 中标服务费，若不涉及请写0 招标服务费以中标金额为计算基数，参照国家计委计价格【2002】1980号文标准计取。100万元以下的【服务类招标】，按照1.5%收取招标代理服务费 | M30: =G30/(1+H30)*H30 -> 0
C31: 无 | D31: 附加税 | E31: 1 | F31: 无 | G31: =IF((M10-M31)*0.12>0,(M10-M31)*0.12,0) -> 1720.9477 | I31: =G31 -> 1720.9477 | J31: 0元 | L31: 附加税自动计算，请勿修改公式 | M31: =SUM(M13:M30) -> 11696.505
C32: 无 | D32: 垫资成本 | E32: 1 | F32: 无 | G32: =SUM(K40:K55) -> 0 | I32: =G32 -> 0 | J32: 0元 | L32: 垫资成本=垫资金额*垫资月数*0.5%
G33: =SUM(G13:G32) -> 403300.95 | I33: =SUM(I13:I32) -> 391604.44 | J33: =SUM(J13:J28) -> 0
A34: 三、其他合同列表（该部分不参与利润核算）
A35: 序号 | B35: 合同编号 | C35: 供应商 | D35: 采购内容 | E35: 合同名称 | G35: 合同金额（元） | K35: 签订日期 | L35: 备注
A37: 其他合同额总计： | G37: =SUM(G36:G36) -> 0
A38: 四、资金收支预计表（包括销售合同、采购\分包合同、履约保证金等所有资金的收付）
A39: 序号 | B39: 合同编号 | C39: 合同预计收/付款日期 | D39: 客户/供应商 | E39: 收/付款条件 | F39: 收款金额 | G39: 付款金额 | H39: 结余（元） | I39: 垫资天数 | J39: 垫资金额 | K39: 垫资成本 | L39: 备注(实收实付情况）
A40: 1 | C40: 46053 | D40: 澄迈睡个好觉品牌管理有限公司 | E40: 首付款：合同生效，且乙方提交《项目开发计划表》并甲方确认后7个工作日内，甲方支付总金额的50%，即人民币230000.00元（大写：贰拾叁万圆整） | F40: 230000 | H40: =IF(C40="","",F40-G40) -> 230000 | I40: =IF(H40<0,C41-C40,0) -> 0 | J40: =IF(H40<0,-H40,0) -> 0 | K40: =J40*I40/365*6% -> 0
A41: 2 | C41: 46081 | D41: 陕西百格数据科技有限责任公司 | G41: =G13*0.5 -> 200790 | H41: =IF(C41="","",H40+F41-G41) -> 29210 | I41: =IF(H41<0,C42-C41,0) -> 0 | J41: =IF(H41<0,-H41,0) -> 0 | K41: =J41*I41/365*6% -> 0
...

Sheet 人工及费用测算
B1: 黄色底色需手动填写
B2: 第一部分：人天计划及人工成本
C3: 总人天 | D3: =J10 -> 1
C4: 总人工成本（不含税） | D4: =I10 -> 1.5789474
C5: 人天成本（CostRate） | D5: =D4/D3 -> 1.5789474
K8: 2025 | W8: 2026 | AI8: 2027 | AV8: 2025 | BH8: 2026 | BT8: 2027
B9: 阶段 | G9: 职级取公司内部职级 | J9: 投入工作日天数 | K9: 19 | L9: 19 | M9: 21 | N9: 22 | O9: 19 | P9: 20 | Q9: 23 | R9: 21 | S9: 23 | T9: 18 | U9: 20 | V9: 23 | W9: 19 | X9: 19 | Y9: 21 | Z9: 22 | AA9: 19 | AB9: 20 | AC9: 23 | AD9: 21 | AE9: 23 | AF9: 18 | AG9: 20 | AH9: 23 | AI9: 19 | AJ9: 19 | AK9: 21 | AL9: 22 | AM9: 19 | AN9: 20 | AO9: 23 | AP9: 21 | AQ9: 23 | AR9: 18 | AS9: 20 | AT9: 23 | AV9: 19 | AW9: 19 | AX9: 21 | AY9: 22 | AZ9: 19 | BA9: 20 | BB9: 23 | BC9: 21 | BD9: 23 | BE9: 18 | BF9: 20 | BG9: 23 | BH9: 19 | BI9: 19 | BJ9: 21 | BK9: 22 | BL9: 19 | BM9: 20 | BN9: 23 | BO9: 21 | BP9: 23 | BQ9: 18 | BR9: 20 | BS9: 23 | BT9: 19 | BU9: 19 | BV9: 21 | BW9: 22 | BX9: 19 | BY9: 20 | BZ9: 23 | CA9: 21 | CB9: 23 | CC9: 18 | CD9: 20 | CE9: 23
I10: =SUM(I12:I51) -> 1.5789474 | J10: =SUM(J12:J51) -> 1 | K10: 1 | L10: =IF(K10=12,1,K10+1) -> 2 | M10: =IF(L10=12,1,L10+1) -> 3 | N10: =IF(M10=12,1,M10+1) -> 4 | O10: =IF(N10=12,1,N10+1) -> 5 | P10: =IF(O10=12,1,O10+1) -> 6 | Q10: =IF(P10=12,1,P10+1) -> 7 | R10: =IF(Q10=12,1,Q10+1) -> 8 | S10: =IF(R10=12,1,R10+1) -> 9 | ... AT10: =IF(AS10=12,1,AS10+1) -> 12 | AU10: =SUM(AU12:AU51) -> 1 | AV10: 1 | AW10: =IF(AV10=12,1,AV10+1) -> 2 | AX10: =IF(AW10=12,1,AW10+1) -> 3 | AY10: =IF(AX10=12,1,AX10+1) -> 4 | AZ10: =IF(AY10=12,1,AY10+1) -> 5 | BA10: =IF(AZ10=12,1,AZ10+1) -> 6 | BB10: =IF(BA10=12,1,BA10+1) -> 7 | BC10: =IF(BB10=12,1,BB10+1) -> 8 | BD10: =IF(BC10=12,1,BC10+1) -> 9 | ... CE10: =IF(CD10=12,1,CD10+1) -> 12
B11: NO. | C11: 里程碑阶段 | D11: 岗位 | E11: 姓名 | F11: 人员归属部门 | G11: base | H11: cost Rate(含薪酬及五险一金，人月） | I11: 总人工成本（不含税） | J11: 投入工作日汇总 | K11: =SUM(K12:K51) -> 1 | L11: =SUM(L12:L51) -> 0 | M11: =SUM(M12:M51) -> 0 | N11: =SUM(N12:N51) -> 0 | O11: =SUM(O12:O51) -> 0 | P11: =SUM(P12:P51) -> 0 | Q11: =SUM(Q12:Q51) -> 0 | R11: =SUM(R12:R51) -> 0 | ... AT11: =SUM(AT12:AT51) -> 0 | AU11: 投入月份个数 | AV11: =SUM(AV12:AV51) -> 1.5789474 | AW11: =SUM(AW12:AW51) -> 0 | AX11: =SUM(AX12:AX51) -> 0 | AY11: =SUM(AY12:AY51) -> 0 | AZ11: =SUM(AZ12:AZ51) -> 0 | BA11: =SUM(BA12:BA51) -> 0 | BB11: =SUM(BB12:BB51) -> 0 | BC11: =SUM(BC12:BC51) -> 0 | ... CE11: =SUM(CE12:CE51) -> 0
B12: 1 | H12: 30 | I12: =SUM(AV12:CE12) -> 1.5789474 | J12: =SUM(K12:AT12) -> 1 | K12: 1 | AU12: =COUNTA(K12:AT12) -> 1 | AV12: =$H12/K$9*K12 -> 1.5789474 | AW12: =$H12/L$9*L12 -> 0 | AX12: =$H12/M$9*M12 -> 0 | AY12: =$H12/N$9*N12 -> 0 | AZ12: =$H12/O$9*O12 -> 0 | BA12: =$H12/P$9*P12 -> 0 | BB12: =$H12/Q$9*Q12 -> 0 | BC12: =$H12/R$9*R12 -> 0 | ... CE12: =$H12/AT$9*AT12 -> 0
B13: 2 | J13: =SUM(K13:AT13) -> 0 | AU13: =COUNTA(K13:AT13) -> 0 | AV13: =$H13/K$9*K13 -> 0 | AW13: =$H13/L$9*L13 -> 0 | AX13: =$H13/M$9*M13 -> 0 | AY13: =$H13/N$9*N13 -> 0 | AZ13: =$H13/O$9*O13 -> 0 | BA13: =$H13/P$9*P13 -> 0 | BB13: =$H13/Q$9*Q13 -> 0 | BC13: =$H13/R$9*R13 -> 0 | ... CE13: =$H13/AT$9*AT13 -> 0
B14: 3 | J14: =SUM(K14:AT14) -> 0 | AU14: =COUNTA(K14:AT14) -> 0 | AV14: =$H14/K$9*K14 -> 0 | AW14: =$H14/L$9*L14 -> 0 | AX14: =$H14/M$9*M14 -> 0 | AY14: =$H14/N$9*N14 -> 0 | AZ14: =$H14/O$9*O14 -> 0 | BA14: =$H14/P$9*P14 -> 0 | BB14: =$H14/Q$9*Q14 -> 0 | BC14: =$H14/R$9*R14 -> 0 | ... CE14: =$H14/AT$9*AT14 -> 0
B15: 4 | J15: =SUM(K15:AT15) -> 0 | AU15: =COUNTA(K15:AT15) -> 0 | AV15: =$H15/K$9*K15 -> 0 | AW15: =$H15/L$9*L15 -> 0 | AX15: =$H15/M$9*M15 -> 0 | AY15: =$H15/N$9*N15 -> 0 | AZ15: =$H15/O$9*O15 -> 0 | BA15: =$H15/P$9*P15 -> 0 | BB15: =$H15/Q$9*Q15 -> 0 | BC15: =$H15/R$9*R15 -> 0 | ... CE15: =$H15/AT$9*AT15 -> 0
B16: 5 | J16: =SUM(K16:AT16) -> 0 | AU16: =COUNTA(K16:AT16) -> 0 | AV16: =$H16/K$9*K16 -> 0 | AW16: =$H16/L$9*L16 -> 0 | AX16: =$H16/M$9*M16 -> 0 | AY16: =$H16/N$9*N16 -> 0 | AZ16: =$H16/O$9*O16 -> 0 | BA16: =$H16/P$9*P16 -> 0 | BB16: =$H16/Q$9*Q16 -> 0 | BC16: =$H16/R$9*R16 -> 0 | ... CE16: =$H16/AT$9*AT16 -> 0
B17: 6 | J17: =SUM(K17:AT17) -> 0 | AU17: =COUNTA(K17:AT17) -> 0 | AV17: =$H17/K$9*K17 -> 0 | AW17: =$H17/L$9*L17 -> 0 | AX17: =$H17/M$9*M17 -> 0 | AY17: =$H17/N$9*N17 -> 0 | AZ17: =$H17/O$9*O17 -> 0 | BA17: =$H17/P$9*P17 -> 0 | BB17: =$H17/Q$9*Q17 -> 0 | BC17: =$H17/R$9*R17 -> 0 | ... CE17: =$H17/AT$9*AT17 -> 0
B18: 7 | J18: =SUM(K18:AT18) -> 0 | AU18: =COUNTA(K18:AT18) -> 0 | AV18: =$H18/K$9*K18 -> 0 | AW18: =$H18/L$9*L18 -> 0 | AX18: =$H18/M$9*M18 -> 0 | AY18: =$H18/N$9*N18 -> 0 | AZ18: =$H18/O$9*O18 -> 0 | BA18: =$H18/P$9*P18 -> 0 | BB18: =$H18/Q$9*Q18 -> 0 | BC18: =$H18/R$9*R18 -> 0 | ... CE18: =$H18/AT$9*AT18 -> 0
B19: 8 | J19: =SUM(K19:AT19) -> 0 | AU19: =COUNTA(K19:AT19) -> 0 | AV19: =$H19/K$9*K19 -> 0 | AW19: =$H19/L$9*L19 -> 0 | AX19: =$H19/M$9*M19 -> 0 | AY19: =$H19/N$9*N19 -> 0 | AZ19: =$H19/O$9*O19 -> 0 | BA19: =$H19/P$9*P19 -> 0 | BB19: =$H19/Q$9*Q19 -> 0 | BC19: =$H19/R$9*R19 -> 0 | ... CE19: =$H19/AT$9*AT19 -> 0
B20: 9 | J20: =SUM(K20:AT20) -> 0 | AU20: =COUNTA(K20:AT20) -> 0 | AV20: =$H20/K$9*K20 -> 0 | AW20: =$H20/L$9*L20 -> 0 | AX20: =$H20/M$9*M20 -> 0 | AY20: =$H20/N$9*N20 -> 0 | AZ20: =$H20/O$9*O20 -> 0 | BA20: =$H20/P$9*P20 -> 0 | BB20: =$H20/Q$9*Q20 -> 0 | BC20: =$H20/R$9*R20 -> 0 | ... CE20: =$H20/AT$9*AT20 -> 0
B21: 10 | J21: =SUM(K21:AT21) -> 0 | AU21: =COUNTA(K21:AT21) -> 0 | AV21: =$H21/K$9*K21 -> 0 | AW21: =$H21/L$9*L21 -> 0 | AX21: =$H21/M$9*M21 -> 0 | AY21: =$H21/N$9*N21 -> 0 | AZ21: =$H21/O$9*O21 -> 0 | BA21: =$H21/P$9*P21 -> 0 | BB21: =$H21/Q$9*Q21 -> 0 | BC21: =$H21/R$9*R21 -> 0 | ... CE21: =$H21/AT$9*AT21 -> 0
B22: 11 | J22: =SUM(K22:AT22) -> 0 | AU22: =COUNTA(K22:AT22) -> 0 | AV22: =$H22/K$9*K22 -> 0 | AW22: =$H22/L$9*L22 -> 0 | AX22: =$H22/M$9*M22 -> 0 | AY22: =$H22/N$9*N22 -> 0 | AZ22: =$H22/O$9*O22 -> 0 | BA22: =$H22/P$9*P22 -> 0 | BB22: =$H22/Q$9*Q22 -> 0 | BC22: =$H22/R$9*R22 -> 0 | ... CE22: =$H22/AT$9*AT22 -> 0
B23: 12 | J23: =SUM(K23:AT23) -> 0 | AU23: =COUNTA(K23:AT23) -> 0 | AV23: =$H23/K$9*K23 -> 0 | AW23: =$H23/L$9*L23 -> 0 | AX23: =$H23/M$9*M23 -> 0 | AY23: =$H23/N$9*N23 -> 0 | AZ23: =$H23/O$9*O23 -> 0 | BA23: =$H23/P$9*P23 -> 0 | BB23: =$H23/Q$9*Q23 -> 0 | BC23: =$H23/R$9*R23 -> 0 | ... CE23: =$H23/AT$9*AT23 -> 0
B24: 13 | J24: =SUM(K24:AT24) -> 0 | AU24: =COUNTA(K24:AT24) -> 0 | AV24: =$H24/K$9*K24 -> 0 | AW24: =$H24/L$9*L24 -> 0 | AX24: =$H24/M$9*M24 -> 0 | AY24: =$H24/N$9*N24 -> 0 | AZ24: =$H24/O$9*O24 -> 0 | BA24: =$H24/P$9*P24 -> 0 | BB24: =$H24/Q$9*Q24 -> 0 | BC24: =$H24/R$9*R24 -> 0 | ... CE24: =$H24/AT$9*AT24 -> 0
... B51: 40 | J51: =SUM(K51:AT51) -> 0 | AU51: =COUNTA(K51:AT51) -> 0 | AV51: =$H51/K$9*K51 -> 0 | AW51: =$H51/L$9*L51 -> 0 | AX51: =$H51/M$9*M51 -> 0 | AY51: =$H51/N$9*N51 -> 0 | AZ51: =$H51/O$9*O51 -> 0 | BA51: =$H51/P$9*P51 -> 0 | BB51: =$H51/Q$9*Q51 -> 0 | BC51: =$H51/R$9*R51 -> 0 | ... CE51: =$H51/AT$9*AT51 -> 0
B53: 第二部分：差旅及其他费用
C54: 总人月 | D54: =D3/20.67 -> 0.048379294
C55: 差旅成本 | D55: =D62+D63+D64 -> 0
C56: 人均单月差旅 | D56: =D55/D54 -> 0
E58: 2025 | Q58: 2026 | AC58: 2027
D59: 投入工作日天数 | E59: 19 | F59: 19 | G59: 21 | H59: 22 | I59: 19 | J59: 20 | K59: 23 | L59: 21 | M59: 23 | N59: 18 | O59: 20 | P59: 23 | Q59: =W9 -> 19 | R59: =X9 -> 19 | S59: =Y9 -> 21 | T59: =Z9 -> 22 | U59: =AA9 -> 19 | V59: =AB9 -> 20 | W59: =AC9 -> 23 | X59: =AD9 -> 21 | ... AN59: =AT9 -> 23
E60: =K10 -> 1 | F60: =IF(E60=12,1,E60+1) -> 2 | G60: =IF(F60=12,1,F60+1) -> 3 | H60: =IF(G60=12,1,G60+1) -> 4 | I60: =IF(H60=12,1,H60+1) -> 5 | J60: =IF(I60=12,1,I60+1) -> 6 | K60: =IF(J60=12,1,J60+1) -> 7 | L60: =IF(K60=12,1,K60+1) -> 8 | M60: =IF(L60=12,1,L60+1) -> 9 | ... AN60: =IF(AM60=12,1,AM60+1) -> 12
C61: 费用类型 | D61: 合计
C62: 项目差旅 | D62: =SUM(E62:AN62) -> 0
C63: 交通费 | D63: =SUM(E63:AN63) -> 0
C64: 其他员工报销费 | D64: =SUM(E64:AN64) -> 0
C65: 合计 | D65: =SUM(D62:D64) -> 0 | E65: =SUM(E62:E64) -> 0 | F65: =SUM(F62:F64) -> 0 | G65: =SUM(G62:G64) -> 0 | H65: =SUM(H62:H64) -> 0 | I65: =SUM(I62:I64) -> 0 | J65: =SUM(J62:J64) -> 0 | K65: =SUM(K62:K64) -> 0 | ... AN65: =SUM(AN62:AN64) -> 0

Sheet 税差辅助测算
B3: 销售金额（元） | C3: 销售合同税率 | D3: 项目留点 | E3: 无税差分包/采购金额 | F3: 供应商发票税率 | G3: 扣除税差后分包/采购金额
A4: 举例 | B4: 1000 | C4: 0.06 | D4: 0.1 | E4: =B4*(1-D4) -> 900 | F4: 0.03 | G4: =E4/(1+C4)*(1+F4) -> 874.5283
E5: =B5*(1-D5) -> 0 | G5: =E5/(1+C5)*(1+F5) -> 0
E6: =B6*(1-D6) -> 0 | G6: =E6/(1+C6)*(1+F6) -> 0
E7: =B7*(1-D7) -> 0 | G7: =E7/(1+C7)*(1+F7) -> 0
E8: =B8*(1-D8) -> 0 | G8: =E8/(1+C8)*(1+F8) -> 0
E9: =B9*(1-D9) -> 0 | G9: =E9/(1+C9)*(1+F9) -> 0
E10: =B10*(1-D10) -> 0 | G10: =E10/(1+C10)*(1+F10) -> 0

Sheet 差旅费测算
L1: 2025年 | BU1: 2026年 | ED1: 2027年
H2: 差旅标准 | L2: 1月 | Q2: 2月 | V2: 3月 | AA2: 4月 | AF2: 5月 | AK2: 6月 | AP2: 7月 | AU2: 8月 | AZ2: 9月 | BE2: 10月 | BJ2: 11月 | BO2: 12月 | BU2: 1月 | BZ2: 2月 | CE2: 3月 | CJ2: 4月 | CO2: 5月 | CT2: 6月 | CY2: 7月 | DD2: 8月 | DI2: 9月 | DN2: 10月 | DS2: 11月 | DX2: 12月 | ED2: 1月 | EI2: 2月 | EN2: 3月 | ES2: 4月 | EX2: 5月 | FC2: 6月 | FH2: 7月 | FM2: 8月 | FR2: 9月 | FW2: 10月 | GB2: 11月 | GG2: 12月
A3: No | B3: 里程碑阶段 | C3: 岗位 | D3: 姓名 | E3: 人员归属部门 | F3: Base | G3: 总计 | H3: 往返路费 | I3: 每日房费 | J3: 每日出差补助 | K3: 2025年合计 | L3: 往返次数 | M3: 住宿天数 | N3: 差旅总额 | O3: 交通费 | P3: 其他 | Q3: 往返次数 | R3: 住宿天数 | S3: 差旅总额 | T3: 交通费 | U3: 其他 | V3: 往返次数 | W3: 住宿天数 | X3: 差旅总额 | Y3: 交通费 | Z3: 其他 | AA3: 往返次数 | AB3: 住宿天数 | AC3: 差旅总额 | AD3: 交通费 | AE3: 其他 | AF3: 往返次数 | AG3: 住宿天数 | AH3: 差旅总额 | AI3: 交通费 | AJ3: 其他 | AK3: 往返次数 | AL3: 住宿天数 | AM3: 差旅总额 | AN3: 交通费 | AO3: 其他 | AP3: 往返次数 | AQ3: 住宿天数 | AR3: 差旅总额 | AS3: 交通费 | AT3: 其他 | AU3: 往返次数 | AV3: 住宿天数 | AW3: 差旅总额 | AX3: 交通费 | AY3: 其他 | AZ3: 往返次数 | BA3: 住宿天数 | BB3: 差旅总额 | BC3: 交通费 | BD3: 其他 | BE3: 往返次数 | BF3: 住宿天数 | BG3: 差旅总额 | BH3: 交通费 | BI3: 其他 | BJ3: 往返次数 | BK3: 住宿天数 | BL3: 差旅总额 | BM3: 交通费 | BN3: 其他 | BO3: 往返次数 | BP3: 住宿天数 | BQ3: 差旅总额 | BR3: 交通费 | BS3: 其他 | BT3: 2026年合计 | BU3: 往返次数 | BV3: 住宿天数 | BW3: 差旅总额 | BX3: 交通费 | BY3: 其他 | BZ3: 往返次数 | CA3: 住宿天数 | CB3: 差旅总额 | CC3: 交通费 | CD3: 其他 | CE3: 往返次数 | CF3: 住宿天数 | CG3: 差旅总额 | CH3: 交通费 | CI3: 其他 | CJ3: 往返次数 | CK3: 住宿天数 | CL3: 差旅总额 | CM3: 交通费 | CN3: 其他 | CO3: 往返次数 | CP3: 住宿天数 | CQ3: 差旅总额 | CR3: 交通费 | CS3: 其他 | CT3: 往返次数 | CU3: 住宿天数 | CV3: 差旅总额 | CW3: 交通费 | CX3: 其他 | CY3: 往返次数 | CZ3: 住宿天数 | DA3: 差旅总额 | DB3: 交通费 | DC3: 其他 | DD3: 往返次数 | DE3: 住宿天数 | DF3: 差旅总额 | DG3: 交通费 | DH3: 其他 | DI3: 往返次数 | DJ3: 住宿天数 | DK3: 差旅总额 | DL3: 交通费 | DM3: 其他 | DN3: 往返次数 | DO3: 住宿天数 | DP3: 差旅总额 | DQ3: 交通费 | DR3: 其他 | DS3: 往返次数 | DT3: 住宿天数 | DU3: 差旅总额 | DV3: 交通费 | DW3: 其他 | DX3: 往返次数 | DY3: 住宿天数 | DZ3: 差旅总额 | EA3: 交通费 | EB3: 其他 | EC3: 2027年合计 | ED3: 往返次数 | EE3: 住宿天数 | EF3: 差旅总额 | EG3: 交通费 | EH3: 其他 | EI3: 往返次数 | EJ3: 住宿天数 | EK3: 差旅总额 | EL3: 交通费 | EM3: 其他 | EN3: 往返次数 | EO3: 住宿天数 | EP3: 差旅总额 | EQ3: 交通费 | ER3: 其他 | ES3: 往返次数 | ET3: 住宿天数 | EU3: 差旅总额 | EV3: 交通费 | EW3: 其他 | EX3: 往返次数 | EY3: 住宿天数 | EZ3: 差旅总额 | FA3: 交通费 | FB3: 其他 | FC3: 往返次数 | FD3: 住宿天数 | FE3: 差旅总额 | FF3: 交通费 | FG3: 其他 | FH3: 往返次数 | FI3: 住宿天数 | FJ3: 差旅总额 | FK3: 交通费 | FL3: 其他 | FM3: 往返次数 | FN3: 住宿天数 | FO3: 差旅总额 | FP3: 交通费 | FQ3: 其他 | FR3: 往返次数 | FS3: 住宿天数 | FT3: 差旅总额 | FU3: 交通费 | FV3: 其他 | FW3: 往返次数 | FX3: 住宿天数 | FY3: 差旅总额 | FZ3: 交通费 | GA3: 其他 | GB3: 往返次数 | GC3: 住宿天数 | GD3: 差旅总额 | GE3: 交通费 | GF3: 其他 | GG3: 往返次数 | GH3: 住宿天数 | GI3: 差旅总额 | GJ3: 交通费 | GK3: 其他
A4: 1 | B4: =[1]项目立项!C24 -> 0 | C4: =[1]项目立项!D24 -> 0 | D4: =[1]项目立项!E24 -> 0 | E4: =[1]项目立项!F24 -> 0 | G4: =K4+BT4+EC4 -> 0 | K4: =SUM(N4:P4,S4:U4,X4:Z4,AC4:AE4,AH4:AJ4,AM4:AO4,AR4:AT4,AW4:AY4,BB4:BD4,BG4:BI4,BL4:BN4,BQ4:BS4) -> 0 | N4: =L4*$H4+($I4+$J4)*M4 -> 0 | S4: =Q4*$H4+($I4+$J4)*R4 -> 0 | X4: =V4*$H4+($I4+$J4)*W4 -> 0 | AC4: =AA4*$H4+($I4+$J4)*AB4 -> 0 | AH4: =AF4*$H4+($I4+$J4)*AG4 -> 0 | AM4: =AK4*$H4+($I4+$J4)*AL4 -> 0 | AR4: =AP4*$H4+($I4+$J4)*AQ4 -> 0 | AW4: =AU4*$H4+($I4+$J4)*AV4 -> 0 | BB4: =AZ4*$H4+($I4+$J4)*BA4 -> 0 | BG4: =BE4*$H4+($I4+$J4)*BF4 -> 0 | BL4: =BJ4*$H4+($I4+$J4)*BK4 -> 0 | BQ4: =BO4*$H4+($I4+$J4)*BP4 -> 0 | BT4: =SUM(BW4:BY4,CB4:CD4,CG4:CI4,CL4:CN4,CQ4:CS4,CV4:CX4,DA4:DC4,DF4:DH4,DK4:DM4,DP4:DR4,DU4:DW4,DZ4:EB4) -> 0 | BW4: =BU4*$H4+($I4+$J4)*BV4 -> 0 | CB4: =BZ4*$H4+($I4+$J4)*CA4 -> 0 | CG4: =CE4*$H4+($I4+$J4)*CF4 -> 0 | CL4: =CJ4*$H4+($I4+$J4)*CK4 -> 0 | CQ4: =CO4*$H4+($I4+$J4)*CP4 -> 0 | CV4: =CT4*$H4+($I4+$J4)*CU4 -> 0 | DA4: =CY4*$H4+($I4+$J4)*CZ4 -> 0 | DF4: =DD4*$H4+($I4+$J4)*DE4 -> 0 | DK4: =DI4*$H4+($I4+$J4)*DJ4 -> 0 | DP4: =DN4*$H4+($I4+$J4)*DO4 -> 0 | DU4: =DS4*$H4+($I4+$J4)*DT4 -> 0 | DZ4: =DX4*$H4+($I4+$J4)*DY4 -> 0 | EC4: =SUM(EF4:EH4,EK4:EM4,EP4:ER4,EU4:EW4,EZ4:FB4,FE4:FG4,FJ4:FL4,FO4:FQ4,FT4:FV4,FY4:GA4,GD4:GF4,GI4:GK4) -> 0 | EF4: =ED4*$H4+($I4+$J4)*EE4 -> 0 | EK4: =EI4*$H4+($I4+$J4)*EJ4 -> 0 | EP4: =EN4*$H4+($I4+$J4)*EO4 -> 0 | EU4: =ES4*$H4+($I4+$J4)*ET4 -> 0 | EZ4: =EX4*$H4+($I4+$J4)*EY4 -> 0 | FE4: =FC4*$H4+($I4+$J4)*FD4 -> 0 | FJ4: =FH4*$H4+($I4+$J4)*FI4 -> 0 | FO4: =FM4*$H4+($I4+$J4)*FN4 -> 0 | FT4: =FR4*$H4+($I4+$J4)*FS4 -> 0 | FY4: =FW4*$H4+($I4+$J4)*FX4 -> 0 | GD4: =GB4*$H4+($I4+$J4)*GC4 -> 0 | GI4: =GG4*$H4+($I4+$J4)*GH4 -> 0
A5: 2 | B5: =[1]项目立项!C25 -> 0 | C5: =[1]项目立项!D25 -> 0 | D5: =[1]项目立项!E25 -> 0 | E5: =[1]项目立项!F25 -> 0 | G5: =K5+BT5+EC5 -> 0 | K5: =SUM(N5:P5,S5:U5,X5:Z5,AC5:AE5,AH5:AJ5,AM5:AO5,AR5:AT5,AW5:AY5,BB5:BD5,BG5:BI5,BL5:BN5,BQ5:BS5) -> 0 | N5: =L5*$H5+($I5+$J5)*M5 -> 0 | S5: =Q5*$H5+($I5+$J5)*R5 -> 0 | X5: =V5*$H5+($I5+$J5)*W5 -> 0 | AC5: =AA5*$H5+($I5+$J5)*AB5 -> 0 | AH5: =AF5*$H5+($I5+$J5)*AG5 -> 0 | AM5: =AK5*$H5+($I5+$J5)*AL5 -> 0 | AR5: =AP5*$H5+($I5+$J5)*AQ5 -> 0 | AW5: =AU5*$H5+($I5+$J5)*AV5 -> 0 | BB5: =AZ5*$H5+($I5+$J5)*BA5 -> 0 | BG5: =BE5*$H5+($I5+$J5)*BF5 -> 0 | BL5: =BJ5*$H5+($I5+$J5)*BK5 -> 0 | BQ5: =BO5*$H5+($I5+$J5)*BP5 -> 0 | BT5: =SUM(BW5:BY5,CB5:CD5,CG5:CI5,CL5:CN5,CQ5:CS5,CV5:CX5,DA5:DC5,DF5:DH5,DK5:DM5,DP5:DR5,DU5:DW5,DZ5:EB5) -> 0 | BW5: =BU5*$H5+($I5+$J5)*BV5 -> 0 | CB5: =BZ5*$H5+($I5+$J5)*CA5 -> 0 | CG5: =CE5*$H5+($I5+$J5)*CF5 -> 0 | CL5: =CJ5*$H5+($I5+$J5)*CK5 -> 0 | CQ5: =CO5*$H5+($I5+$J5)*CP5 -> 0 | CV5: =CT5*$H5+($I5+$J5)*CU5 -> 0 | DA5: =CY5*$H5+($I5+$J5)*CZ5 -> 0 | DF5: =DD5*$H5+($I5+$J5)*DE5 -> 0 | DK5: =DI5*$H5+($I5+$J5)*DJ5 -> 0 | DP5: =DN5*$H5+($I5+$J5)*DO5 -> 0 | DU5: =DS5*$H5+($I5+$J5)*DT5 -> 0 | DZ5: =DX5*$H5+($I5+$J5)*DY5 -> 0 | EC5: =SUM(EF5:EH5,EK5:EM5,EP5:ER5,EU5:EW5,EZ5:FB5,FE5:FG5,FJ5:FL5,FO5:FQ5,FT5:FV5,FY5:GA5,GD5:GF5,GI5:GK5) -> 0 | EF5: =ED5*$H5+($I5+$J5)*EE5 -> 0 | EK5: =EI5*$H5+($I5+$J5)*EJ5 -> 0 | EP5: =EN5*$H5+($I5+$J5)*EO5 -> 0 | EU5: =ES5*$H5+($I5+$J5)*ET5 -> 0 | EZ5: =EX5*$H5+($I5+$J5)*EY5 -> 0 | FE5: =FC5*$H5+($I5+$J5)*FD5 -> 0 | FJ5: =FH5*$H5+($I5+$J5)*FI5 -> 0 | FO5: =FM5*$H5+($I5+$J5)*FN5 -> 0 | FT5: =FR5*$H5+($I5+$J5)*FS5 -> 0 | FY5: =FW5*$H5+($I5+$J5)*FX5 -> 0 | GD5: =GB5*$H5+($I5+$J5)*GC5 -> 0 | GI5: =GG5*$H5+($I5+$J5)*GH5 -> 0
A6: 3 | B6: =[1]项目立项!C26 -> 0 | C6: =[1]项目立项!D26 -> 0 | D6: =[1]项目立项!E26 -> 0 | E6: =[1]项目立项!F26 -> 0 | G6: =K6+BT6+EC6 -> 0 | K6: =SUM(N6:P6,S6:U6,X6:Z6,AC6:AE6,AH6:AJ6,AM6:AO6,AR6:AT6,AW6:AY6,BB6:BD6,BG6:BI6,BL6:BN6,BQ6:BS6) -> 0 | N6: =L6*$H6+($I6+$J6)*M6 -> 0 | S6: =Q6*$H6+($I6+$J6)*R6 -> 0 | X6: =V6*$H6+($I6+$J6)*W6 -> 0 | AC6: =AA6*$H6+($I6+$J6)*AB6 -> 0 | AH6: =AF6*$H6+($I6+$J6)*AG6 -> 0 | AM6: =AK6*$H6+($I6+$J6)*AL6 -> 0 | AR6: =AP6*$H6+($I6+$J6)*AQ6 -> 0 | AW6: =AU6*$H6+($I6+$J6)*AV6 -> 0 | BB6: =AZ6*$H6+($I6+$J6)*BA6 -> 0 | BG6: =BE6*$H6+($I6+$J6)*BF6 -> 0 | BL6: =BJ6*$H6+($I6+$J6)*BK6 -> 0 | BQ6: =BO6*$H6+($I6+$J6)*BP6 -> 0 | BT6: =SUM(BW6:BY6,CB6:CD6,CG6:CI6,CL6:CN6,CQ6:CS6,CV6:CX6,DA6:DC6,DF6:DH6,DK6:DM6,DP6:DR6,DU6:DW6,DZ6:EB6) -> 0 | BW6: =BU6*$H6+($I6+$J6)*BV6 -> 0 | CB6: =BZ6*$H6+($I6+$J6)*CA6 -> 0 | CG6: =CE6*$H6+($I6+$J6)*CF6 -> 0 | CL6: =CJ6*$H6+($I6+$J6)*CK6 -> 0 | CQ6: =CO6*$H6+($I6+$J6)*CP6 -> 0 | CV6: =CT6*$H6+($I6+$J6)*CU6 -> 0 | DA6: =CY6*$H6+($I6+$J6)*CZ6 -> 0 | DF6: =DD6*$H6+($I6+$J6)*DE6 -> 0 | DK6: =DI6*$H6+($I6+$J6)*DJ6 -> 0 | DP6: =DN6*$H6+($I6+$J6)*DO6 -> 0 | DU6: =DS6*$H6+($I6+$J6)*DT6 -> 0 | DZ6: =DX6*$H6+($I6+$J6)*DY6 -> 0 | EC6: =SUM(EF6:EH6,EK6:EM6,EP6:ER6,EU6:EW6,EZ6:FB6,FE6:FG6,FJ6:FL6,FO6:FQ6,FT6:FV6,FY6:GA6,GD6:GF6,GI6:GK6) -> 0 | EF6: =ED6*$H6+($I6+$J6)*EE6 -> 0 | EK6: =EI6*$H6+($I6+$J6)*EJ6 -> 0 | EP6: =EN6*$H6+($I6+$J6)*EO6 -> 0 | EU6: =ES6*$H6+($I6+$J6)*ET6 -> 0 | EZ6: =EX6*$H6+($I6+$J6)*EY6 -> 0 | FE6: =FC6*$H6+($I6+$J6)*FD6 -> 0 | FJ6: =FH6*$H6+($I6+$J6)*FI6 -> 0 | FO6: =FM6*$H6+($I6+$J6)*FN6 -> 0 | FT6: =FR6*$H6+($I6+$J6)*FS6 -> 0 | FY6: =FW6*$H6+($I6+$J6)*FX6 -> 0 | GD6: =GB6*$H6+($I6+$J6)*GC6 -> 0 | GI6: =GG6*$H6+($I6+$J6)*GH6 -> 0
A7: 4 | B7: =[1]项目立项!C27 -> 0 | C7: =[1]项目立项!D27 -> 0 | D7: =[1]项目立项!E27 -> 0 | E7: =[1]项目立项!F27 -> 0 | G7: =K7+BT7+EC7 -> 0 | K7: =SUM(N7:P7,S7:U7,X7:Z7,AC7:AE7,AH7:AJ7,AM7:AO7,AR7:AT7,AW7:AY7,BB7:BD7,BG7:BI7,BL7:BN7,BQ7:BS7) -> 0 | N7: =L7*$H7+($I7+$J7)*M7 -> 0 | S7: =Q7*$H7+($I7+$J7)*R7 -> 0 | X7: =V7*$H7+($I7+$J7)*W7 -> 0 | AC7: =AA7*$H7+($I7+$J7)*AB7 -> 0 | AH7: =AF7*$H7+($I7+$J7)*AG7 -> 0 | AM7: =AK7*$H7+($I7+$J7)*AL7 -> 0 | AR7: =AP7*$H7+($I7+$J7)*AQ7 -> 0 | AW7: =AU7*$H7+($I7+$J7)*AV7 -> 0 | BB7: =AZ7*$H7+($I7+$J7)*BA7 -> 0 | BG7: =BE7*$H7+($I7+$J7)*BF7 -> 0 | BL7: =BJ7*$H7+($I7+$J7)*BK7 -> 0 | BQ7: =BO7*$H7+($I7+$J7)*BP7 -> 0 | BT7: =SUM(BW7:BY7,CB7:CD7,CG7:CI7,CL7:CN7,CQ7:CS7,CV7:CX7,DA7:DC7,DF7:DH7,DK7:DM7,DP7:DR7,DU7:DW7,DZ7:EB7) -> 0 | BW7: =BU7*$H7+($I7+$J7)*BV7 -> 0 | CB7: =BZ7*$H7+($I7+$J7)*CA7 -> 0 | CG7: =CE7*$H7+($I7+$J7)*CF7 -> 0 | CL7: =CJ7*$H7+($I7+$J7)*CK7 -> 0 | CQ7: =CO7*$H7+($I7+$J7)*CP7 -> 0 | CV7: =CT7*$H7+($I7+$J7)*CU7 -> 0 | DA7: =CY7*$H7+($I7+$J7)*CZ7 -> 0 | DF7: =DD7*$H7+($I7+$J7)*DE7 -> 0 | DK7: =DI7*$H7+($I7+$J7)*DJ7 -> 0 | DP7: =DN7*$H7+($I7+$J7)*DO7 -> 0 | DU7: =DS7*$H7+($I7+$J7)*DT7 -> 0 | DZ7: =DX7*$H7+($I7+$J7)*DY7 -> 0 | EC7: =SUM(EF7:EH7,EK7:EM7,EP7:ER7,EU7:EW7,EZ7:FB7,FE7:FG7,FJ7:FL7,FO7:FQ7,FT7:FV7,FY7:GA7,GD7:GF7,GI7:GK7) -> 0 | EF7: =ED7*$H7+($I7+$J7)*EE7 -> 0 | EK7: =EI7*$H7+($I7+$J7)*EJ7 -> 0 | EP7: =EN7*$H7+($I7+$J7)*EO7 -> 0 | EU7: =ES7*$H7+($I7+$J7)*ET7 -> 0 | EZ7: =EX7*$H7+($I7+$J7)*EY7 -> 0 | FE7: =FC7*$H7+($I7+$J7)*FD7 -> 0 | FJ7: =FH7*$H7+($I7+$J7)*FI7 -> 0 | FO7: =FM7*$H7+($I7+$J7)*FN7 -> 0 | FT7: =FR7*$H7+($I7+$J7)*FS7 -> 0 | FY7: =FW7*$H7+($I7+$J7)*FX7 -> 0 | GD7: =GB7*$H7+($I7+$J7)*GC7 -> 0 | GI7: =GG7*$H7+($I7+$J7)*GH7 -> 0
A8: 5 | B8: =[1]项目立项!C28 -> 0 | C8: =[1]项目立项!D28 -> 0 | D8: =[1]项目立项!E28 -> 0 | E8: =[1]项目立项!F28 -> 0 | G8: =K8+BT8+EC8 -> 0 | K8: =SUM(N8:P8,S8:U8,X8:Z8,AC8:AE8,AH8:AJ8,AM8:AO8,AR8:AT8,AW8:AY8,BB8:BD8,BG8:BI8,BL8:BN8,BQ8:BS8) -> 0 | N8: =L8*$H8+($I8+$J8)*M8 -> 0 | S8: =Q8*$H8+($I8+$J8)*R8 -> 0 | X8: =V8*$H8+($I8+$J8)*W8 -> 0 | AC8: =AA8*$H8+($I8+$J8)*AB8 -> 0 | AH8: =AF8*$H8+($I8+$J8)*AG8 -> 0 | AM8: =AK8*$H8+($I8+$J8)*AL8 -> 0 | AR8: =AP8*$H8+($I8+$J8)*AQ8 -> 0 | AW8: =AU8*$H8+($I8+$J8)*AV8 -> 0 | BB8: =AZ8*$H8+($I8+$J8)*BA8 -> 0 | BG8: =BE8*$H8+($I8+$J8)*BF8 -> 0 | BL8: =BJ8*$H8+($I8+$J8)*BK8 -> 0 | BQ8: =BO8*$H8+($I8+$J8)*BP8 -> 0 | BT8: =SUM(BW8:BY8,CB8:CD8,CG8:CI8,CL8:CN8,CQ8:CS8,CV8:CX8,DA8:DC8,DF8:DH8,DK8:DM8,DP8:DR8,DU8:DW8,DZ8:EB8) -> 0 | BW8: =BU8*$H8+($I8+$J8)*BV8 -> 0 | CB8: =BZ8*$H8+($I8+$J8)*CA8 -> 0 | CG8: =CE8*$H8+($I8+$J8)*CF8 -> 0 | CL8: =CJ8*$H8+($I8+$J8)*CK8 -> 0 | CQ8: =CO8*$H8+($I8+$J8)*CP8 -> 0 | CV8: =CT8*$H8+($I8+$J8)*CU8 -> 0 | DA8: =CY8*$H8+($I8+$J8)*CZ8 -> 0 | DF8: =DD8*$H8+($I8+$J8)*DE8 -> 0 | DK8: =DI8*$H8+($I8+$J8)*DJ8 -> 0 | DP8: =DN8*$H8+($I8+$J8)*DO8 -> 0 | DU8: =DS8*$H8+($I8+$J8)*DT8 -> 0 | DZ8: =DX8*$H8+($I8+$J8)*DY8 -> 0 | EC8: =SUM(EF8:EH8,EK8:EM8,EP8:ER8,EU8:EW8,EZ8:FB8,FE8:FG8,FJ8:FL8,FO8:FQ8,FT8:FV8,FY8:GA8,GD8:GF8,GI8:GK8) -> 0 | EF8: =ED8*$H8+($I8+$J8)*EE8 -> 0 | EK8: =EI8*$H8+($I8+$J8)*EJ8 -> 0 | EP8: =EN8*$H8+($I8+$J8)*EO8 -> 0 | EU8: =ES8*$H8+($I8+$J8)*ET8 -> 0 | EZ8: =EX8*$H8+($I8+$J8)*EY8 -> 0 | FE8: =FC8*$H8+($I8+$J8)*FD8 -> 0 | FJ8: =FH8*$H8+($I8+$J8)*FI8 -> 0 | FO8: =FM8*$H8+($I8+$J8)*FN8 -> 0 | FT8: =FR8*$H8+($I8+$J8)*FS8 -> 0 | FY8: =FW8*$H8+($I8+$J8)*FX8 -> 0 | GD8: =GB8*$H8+($I8+$J8)*GC8 -> 0 | GI8: =GG8*$H8+($I8+$J8)*GH8 -> 0
A9: 6 | B9: =[1]项目立项!C29 -> 0 | C9: =[1]项目立项!D29 -> 0 | D9: =[1]项目立项!E29 -> 0 | E9: =[1]项目立项!F29 -> 0 | G9: =K9+BT9+EC9 -> 0 | K9: =SUM(N9:P9,S9:U9,X9:Z9,AC9:AE9,AH9:AJ9,AM9:AO9,AR9:AT9,AW9:AY9,BB9:BD9,BG9:BI9,BL9:BN9,BQ9:BS9) -> 0 | N9: =L9*$H9+($I9+$J9)*M9 -> 0 | S9: =Q9*$H9+($I9+$J9)*R9 -> 0 | X9: =V9*$H9+($I9+$J9)*W9 -> 0 | AC9: =AA9*$H9+($I9+$J9)*AB9 -> 0 | AH9: =AF9*$H9+($I9+$J9)*AG9 -> 0 | AM9: =AK9*$H9+($I9+$J9)*AL9 -> 0 | AR9: =AP9*$H9+($I9+$J9)*AQ9 -> 0 | AW9: =AU9*$H9+($I9+$J9)*AV9 -> 0 | BB9: =AZ9*$H9+($I9+$J9)*BA9 -> 0 | BG9: =BE9*$H9+($I9+$J9)*BF9 -> 0 | BL9: =BJ9*$H9+($I9+$J9)*BK9 -> 0 | BQ9: =BO9*$H9+($I9+$J9)*BP9 -> 0 | BT9: =SUM(BW9:BY9,CB9:CD9,CG9:CI9,CL9:CN9,CQ9:CS9,CV9:CX9,DA9:DC9,DF9:DH9,DK9:DM9,DP9:DR9,DU9:DW9,DZ9:EB9) -> 0 | BW9: =BU9*$H9+($I9+$J9)*BV9 -> 0 | CB9: =BZ9*$H9+($I9+$J9)*CA9 -> 0 | CG9: =CE9*$H9+($I9+$J9)*CF9 -> 0 | CL9: =CJ9*$H9+($I9+$J9)*CK9 -> 0 | CQ9: =CO9*$H9+($I9+$J9)*CP9 -> 0 | CV9: =CT9*$H9+($I9+$J9)*CU9 -> 0 | DA9: =CY9*$H9+($I9+$J9)*CZ9 -> 0 | DF9: =DD9*$H9+($I9+$J9)*DE9 -> 0 | DK9: =DI9*$H9+($I9+$J9)*DJ9 -> 0 | DP9: =DN9*$H9+($I9+$J9)*DO9 -> 0 | DU9: =DS9*$H9+($I9+$J9)*DT9 -> 0 | DZ9: =DX9*$H9+($I9+$J9)*DY9 -> 0 | EC9: =SUM(EF9:EH9,EK9:EM9,EP9:ER9,EU9:EW9,EZ9:FB9,FE9:FG9,FJ9:FL9,FO9:FQ9,FT9:FV9,FY9:GA9,GD9:GF9,GI9:GK9) -> 0 | EF9: =ED9*$H9+($I9+$J9)*EE9 -> 0 | EK9: =EI9*$H9+($I9+$J9)*EJ9 -> 0 | EP9: =EN9*$H9+($I9+$J9)*EO9 -> 0 | EU9: =ES9*$H9+($I9+$J9)*ET9 -> 0 | EZ9: =EX9*$H9+($I9+$J9)*EY9 -> 0 | FE9: =FC9*$H9+($I9+$J9)*FD9 -> 0 | FJ9: =FH9*$H9+($I9+$J9)*FI9 -> 0 | FO9: =FM9*$H9+($I9+$J9)*FN9 -> 0 | FT9: =FR9*$H9+($I9+$J9)*FS9 -> 0 | FY9: =FW9*$H9+($I9+$J9)*FX9 -> 0 | GD9: =GB9*$H9+($I9+$J9)*GC9 -> 0 | GI9: =GG9*$H9+($I9+$J9)*GH9 -> 0
A10: 7 | B10: =[1]项目立项!C30 -> 0 | C10: =[1]项目立项!D30 -> 0 | D10: =[1]项目立项!E30 -> 0 | E10: =[1]项目立项!F30 -> 0 | G10: =K10+BT10+EC10 -> 0 | K10: =SUM(N10:P10,S10:U10,X10:Z10,AC10:AE10,AH10:AJ10,AM10:AO10,AR10:AT10,AW10:AY10,BB10:BD10,BG10:BI10,BL10:BN10,BQ10:BS10) -> 0 | N10: =L10*$H10+($I10+$J10)*M10 -> 0 | S10: =Q10*$H10+($I10+$J10)*R10 -> 0 | X10: =V10*$H10+($I10+$J10)*W10 -> 0 | AC10: =AA10*$H10+($I10+$J10)*AB10 -> 0 | AH10: =AF10*$H10+($I10+$J10)*AG10 -> 0 | AM10: =AK10*$H10+($I10+$J10)*AL10 -> 0 | AR10: =AP10*$H10+($I10+$J10)*AQ10 -> 0 | AW10: =AU10*$H10+($I10+$J10)*AV10 -> 0 | BB10: =AZ10*$H10+($I10+$J10)*BA10 -> 0 | BG10: =BE10*$H10+($I10+$J10)*BF10 -> 0 | BL10: =BJ10*$H10+($I10+$J10)*BK10 -> 0 | BQ10: =BO10*$H10+($I10+$J10)*BP10 -> 0 | BT10: =SUM(BW10:BY10,CB10:CD10,CG10:CI10,CL10:CN10,CQ10:CS10,CV10:CX10,DA10:DC10,DF10:DH10,DK10:DM10,DP10:DR10,DU10:DW10,DZ10:EB10) -> 0 | BW10: =BU10*$H10+($I10+$J10)*BV10 -> 0 | CB10: =BZ10*$H10+($I10+$J10)*CA10 -> 0 | CG10: =CE10*$H10+($I10+$J10)*CF10 -> 0 | CL10: =CJ10*$H10+($I10+$J10)*CK10 -> 0 | CQ10: =CO10*$H10+($I10+$J10)*CP10 -> 0 | CV10: =CT10*$H10+($I10+$J10)*CU10 -> 0 | DA10: =CY10*$H10+($I10+$J10)*CZ10 -> 0 | DF10: =DD10*$H10+($I10+$J10)*DE10 -> 0 | DK10: =DI10*$H10+($I10+$J10)*DJ10 -> 0 | DP10: =DN10*$H10+($I10+$J10)*DO10 -> 0 | DU10: =DS10*$H10+($I10+$J10)*DT10 -> 0 | DZ10: =DX10*$H10+($I10+$J10)*DY10 -> 0 | EC10: =SUM(EF10:EH10,EK10:EM10,EP10:ER10,EU10:EW10,EZ10:FB10,FE10:FG10,FJ10:FL10,FO10:FQ10,FT10:FV10,FY10:GA10,GD10:GF10,GI10:GK10) -> 0 | EF10: =ED10*$H10+($I10+$J10)*EE10 -> 0 | EK10: =EI10*$H10+($I10+$J10)*EJ10 -> 0 | EP10: =EN10*$H10+($I10+$J10)*EO10 -> 0 | EU10: =ES10*$H10+($I10+$J10)*ET10 -> 0 | EZ10: =EX10*$H10+($I10+$J10)*EY10 -> 0 | FE10: =FC10*$H10+($I10+$J10)*FD10 -> 0 | FJ10: =FH10*$H10+($I10+$J10)*FI10 -> 0 | FO10: =FM10*$H10+($I10+$J10)*FN10 -> 0 | FT10: =FR10*$H10+($I10+$J10)*FS10 -> 0 | FY10: =FW10*$H10+($I10+$J10)*FX10 -> 0 | GD10: =GB10*$H10+($I10+$J10)*GC10 -> 0 | GI10: =GG10*$H10+($I10+$J10)*GH10 -> 0
A11: 8 | B11: =[1]项目立项!C31 -> 0 | C11: =[1]项目立项!D31 -> 0 | D11: =[1]项目立项!E31 -> 0 | E11: =[1]项目立项!F31 -> 0 | G11: =K11+BT11+EC11 -> 0 | K11: =SUM(N11:P11,S11:U11,X11:Z11,AC11:AE11,AH11:AJ11,AM11:AO11,AR11:AT11,AW11:AY11,BB11:BD11,BG11:BI11,BL11:BN11,BQ11:BS11) -> 0 | N11: =L11*$H11+($I11+$J11)*M11 -> 0 | S11: =Q11*$H11+($I11+$J11)*R11 -> 0 | X11: =V11*$H11+($I11+$J11)*W11 -> 0 | AC11: =AA11*$H11+($I11+$J11)*AB11 -> 0 | AH11: =AF11*$H11+($I11+$J11)*AG11 -> 0 | AM11: =AK11*$H11+($I11+$J11)*AL11 -> 0 | AR11: =AP11*$H11+($I11+$J11)*AQ11 -> 0 | AW11: =AU11*$H11+($I11+$J11)*AV11 -> 0 | BB11: =AZ11*$H11+($I11+$J11)*BA11 -> 0 | BG11: =BE11*$H11+($I11+$J11)*BF11 -> 0 | BL11: =BJ11*$H11+($I11+$J11)*BK11 -> 0 | BQ11: =BO11*$H11+($I11+$J11)*BP11 -> 0 | BT11: =SUM(BW11:BY11,CB11:CD11,CG11:CI11,CL11:CN11,CQ11:CS11,CV11:CX11,DA11:DC11,DF11:DH11,DK11:DM11,DP11:DR11,DU11:DW11,DZ11:EB11) -> 0 | BW11: =BU11*$H11+($I11+$J11)*BV11 -> 0 | CB11: =BZ11*$H11+($I11+$J11)*CA11 -> 0 | CG11: =CE11*$H11+($I11+$J11)*CF11 -> 0 | CL11: =CJ11*$H11+($I11+$J11)*CK11 -> 0 | CQ11: =CO11*$H11+($I11+$J11)*CP11 -> 0 | CV11: =CT11*$H11+($I11+$J11)*CU11 -> 0 | DA11: =CY11*$H11+($I11+$J11)*CZ11 -> 0 | DF11: =DD11*$H11+($I11+$J11)*DE11 -> 0 | DK11: =DI11*$H11+($I11+$J11)*DJ11 -> 0 | DP11: =DN11*$H11+($I11+$J11)*DO11 -> 0 | DU11: =DS11*$H11+($I11+$J11)*DT11 -> 0 | DZ11: =DX11*$H11+($I11+$J11)*DY11 -> 0 | EC11: =SUM(EF11:EH11,EK11:EM11,EP11:ER11,EU11:EW11,EZ11:FB11,FE11:FG11,FJ11:FL11,FO11:FQ11,FT11:FV11,FY11:GA11,GD11:GF11,GI11:GK11) -> 0 | EF11: =ED11*$H11+($I11+$J11)*EE11 -> 0 | EK11: =EI11*$H11+($I11+$J11)*EJ11 -> 0 | EP11: =EN11*$H11+($I11+$J11)*EO11 -> 0 | EU11: =ES11*$H11+($I11+$J11)*ET11 -> 0 | EZ11: =EX11*$H11+($I11+$J11)*EY11 -> 0 | FE11: =FC11*$H11+($I11+$J11)*FD11 -> 0 | FJ11: =FH11*$H11+($I11+$J11)*FI11 -> 0 | FO11: =FM11*$H11+($I11+$J11)*FN11 -> 0 | FT11: =FR11*$H11+($I11+$J11)*FS11 -> 0 | FY11: =FW11*$H11+($I11+$J11)*FX11 -> 0 | GD11: =GB11*$H11+($I11+$J11)*GC11 -> 0 | GI11: =GG11*$H11+($I11+$J11)*GH11 -> 0
A12: 9 | B12: =[1]项目立项!C32 -> 0 | C12: =[1]项目立项!D32 -> 0 | D12: =[1]项目立项!E32 -> 0 | E12: =[1]项目立项!F32 -> 0 | G12: =K12+BT12+EC12 -> 0 | K12: =SUM(N12:P12,S12:U12,X12:Z12,AC12:AE12,AH12:AJ12,AM12:AO12,AR12:AT12,AW12:AY12,BB12:BD12,BG12:BI12,BL12:BN12,BQ12:BS12) -> 0 | N12: =L12*$H12+($I12+$J12)*M12 -> 0 | S12: =Q12*$H12+($I12+$J12)*R12 -> 0 | X12: =V12*$H12+($I12+$J12)*W12 -> 0 | AC12: =AA12*$H12+($I12+$J12)*AB12 -> 0 | AH12: =AF12*$H12+($I12+$J12)*AG12 -> 0 | AM12: =AK12*$H12+($I12+$J12)*AL12 -> 0 | AR12: =AP12*$H12+($I12+$J12)*AQ12 -> 0 | AW12: =AU12*$H12+($I12+$J12)*AV12 -> 0 | BB12: =AZ12*$H12+($I12+$J12)*BA12 -> 0 | BG12: =BE12*$H12+($I12+$J12)*BF12 -> 0 | BL12: =BJ12*$H12+($I12+$J12)*BK12 -> 0 | BQ12: =BO12*$H12+($I12+$J12)*BP12 -> 0 | BT12: =SUM(BW12:BY12,CB12:CD12,CG12:CI12,CL12:CN12,CQ12:CS12,CV12:CX12,DA12:DC12,DF12:DH12,DK12:DM12,DP12:DR12,DU12:DW12,DZ12:EB12) -> 0 | BW12: =BU12*$H12+($I12+$J12)*BV12 -> 0 | CB12: =BZ12*$H12+($I12+$J12)*CA12 -> 0 | CG12: =CE12*$H12+($I12+$J12)*CF12 -> 0 | CL12: =CJ12*$H12+($I12+$J12)*CK12 -> 0 | CQ12: =CO12*$H12+($I12+$J12)*CP12 -> 0 | CV12: =CT12*$H12+($I12+$J12)*CU12 -> 0 | DA12: =CY12*$H12+($I12+$J12)*CZ12 -> 0 | DF12: =DD12*$H12+($I12+$J12)*DE12 -> 0 | DK12: =DI12*$H12+($I12+$J12)*DJ12 -> 0 | DP12: =DN12*$H12+($I12+$J12)*DO12 -> 0 | DU12: =DS12*$H12+($I12+$J12)*DT12 -> 0 | DZ12: =DX12*$H12+($I12+$J12)*DY12 -> 0 | EC12: =SUM(EF12:EH12,EK12:EM12,EP12:ER12,EU12:EW12,EZ12:FB12,FE12:FG12,FJ12:FL12,FO12:FQ12,FT12:FV12,FY12:GA12,GD12:GF12,GI12:GK12) -> 0 | EF12: =ED12*$H12+($I12+$J12)*EE12 -> 0 | EK12: =EI12*$H12+($I12+$J12)*EJ12 -> 0 | EP12: =EN12*$H12+($I12+$J12)*EO12 -> 0 | EU12: =ES12*$H12+($I12+$J12)*ET12 -> 0 | EZ12: =EX12*$H12+($I12+$J12)*EY12 -> 0 | FE12: =FC12*$H12+($I12+$J12)*FD12 -> 0 | FJ12: =FH12*$H12+($I12+$J12)*FI12 -> 0 | FO12: =FM12*$H12+($I12+$J12)*FN12 -> 0 | FT12: =FR12*$H12+($I12+$J12)*FS12 -> 0 | FY12: =FW12*$H12+($I12+$J12)*FX12 -> 0 | GD12: =GB12*$H12+($I12+$J12)*GC12 -> 0 | GI12: =GG12*$H12+($I12+$J12)*GH12 -> 0
A13: 10 | B13: =[1]项目立项!C33 -> 0 | C13: =[1]项目立项!D33 -> 0 | D13: =[1]项目立项!E33 -> 0 | E13: =[1]项目立项!F33 -> 0 | G13: =K13+BT13+EC13 -> 0 | K13: =SUM(N13:P13,S13:U13,X13:Z13,AC13:AE13,AH13:AJ13,AM13:AO13,AR13:AT13,AW13:AY13,BB13:BD13,BG13:BI13,BL13:BN13,BQ13:BS13) -> 0 | N13: =L13*$H13+($I13+$J13)*M13 -> 0 | S13: =Q13*$H13+($I13+$J13)*R13 -> 0 | X13: =V13*$H13+($I13+$J13)*W13 -> 0 | AC13: =AA13*$H13+($I13+$J13)*AB13 -> 0 | AH13: =AF13*$H13+($I13+$J13)*AG13 -> 0 | AM13: =AK13*$H13+($I13+$J13)*AL13 -> 0 | AR13: =AP13*$H13+($I13+$J13)*AQ13 -> 0 | AW13: =AU13*$H13+($I13+$J13)*AV13 -> 0 | BB13: =AZ13*$H13+($I13+$J13)*BA13 -> 0 | BG13: =BE13*$H13+($I13+$J13)*BF13 -> 0 | BL13: =BJ13*$H13+($I13+$J13)*BK13 -> 0 | BQ13: =BO13*$H13+($I13+$J13)*BP13 -> 0 | BT13: =SUM(BW13:BY13,CB13:CD13,CG13:CI13,CL13:CN13,CQ13:CS13,CV13:CX13,DA13:DC13,DF13:DH13,DK13:DM13,DP13:DR13,DU13:DW13,DZ13:EB13) -> 0 | BW13: =BU13*$H13+($I13+$J13)*BV13 -> 0 | CB13: =BZ13*$H13+($I13+$J13)*CA13 -> 0 | CG13: =CE13*$H13+($I13+$J13)*CF13 -> 0 | CL13: =CJ13*$H13+($I13+$J13)*CK13 -> 0 | CQ13: =CO13*$H13+($I13+$J13)*CP13 -> 0 | CV13: =CT13*$H13+($I13+$J13)*CU13 -> 0 | DA13: =CY13*$H13+($I13+$J13)*CZ13 -> 0 | DF13: =DD13*$H13+($I13+$J13)*DE13 -> 0 | DK13: =DI13*$H13+($I13+$J13)*DJ13 -> 0 | DP13: =DN13*$H13+($I13+$J13)*DO13 -> 0 | DU13: =DS13*$H13+($I13+$J13)*DT13 -> 0 | DZ13: =DX13*$H13+($I13+$J13)*DY13 -> 0 | EC13: =SUM(EF13:EH13,EK13:EM13,EP13:ER13,EU13:EW13,EZ13:FB13,FE13:FG13,FJ13:FL13,FO13:FQ13,FT13:FV13,FY13:GA13,GD13:GF13,GI13:GK13) -> 0 | EF13: =ED13*$H13+($I13+$J13)*EE13 -> 0 | EK13: =EI13*$H13+($I13+$J13)*EJ13 -> 0 | EP13: =EN13*$H13+($I13+$J13)*EO13 -> 0 | EU13: =ES13*$H13+($I13+$J13)*ET13 -> 0 | EZ13: =EX13*$H13+($I13+$J13)*EY13 -> 0 | FE13: =FC13*$H13+($I13+$J13)*FD13 -> 0 | FJ13: =FH13*$H13+($I13+$J13)*FI13 -> 0 | FO13: =FM13*$H13+($I13+$J13)*FN13 -> 0 | FT13: =FR13*$H13+($I13+$J13)*FS13 -> 0 | FY13: =FW13*$H13+($I13+$J13)*FX13 -> 0 | GD13: =GB13*$H13+($I13+$J13)*GC13 -> 0 | GI13: =GG13*$H13+($I13+$J13)*GH13 -> 0
A14: 11 | B14: =[1]项目立项!C34 -> 0 | C14: =[1]项目立项!D34 -> 0 | D14: =[1]项目立项!E34 -> 0 | E14: =[1]项目立项!F34 -> 0 | G14: =K14+BT14+EC14 -> 0 | K14: =SUM(N14:P14,S14:U14,X14:Z14,AC14:AE14,AH14:AJ14,AM14:AO14,AR14:AT14,AW14:AY14,BB14:BD14,BG14:BI14,BL14:BN14,BQ14:BS14) -> 0 | N14: =L14*$H14+($I14+$J14)*M14 -> 0 | S14: =Q14*$H14+($I14+$J14)*R14 -> 0 | X14: =V14*$H14+($I14+$J14)*W14 -> 0 | AC14: =AA14*$H14+($I14+$J14)*AB14 -> 0 | AH14: =AF14*$H14+($I14+$J14)*AG14 -> 0 | AM14: =AK14*$H14+($I14+$J14)*AL14 -> 0 | AR14: =AP14*$H14+($I14+$J14)*AQ14 -> 0 | AW14: =AU14*$H14+($I14+$J14)*AV14 -> 0 | BB14: =AZ14*$H14+($I14+$J14)*BA14 -> 0 | BG14: =BE14*$H14+($I14+$J14)*BF14 -> 0 | BL14: =BJ14*$H14+($I14+$J14)*BK14 -> 0 | BQ14: =BO14*$H14+($I14+$J14)*BP14 -> 0 | BT14: =SUM(BW14:BY14,CB14:CD14,CG14:CI14,CL14:CN14,CQ14:CS14,CV14:CX14,DA14:DC14,DF14:DH14,DK14:DM14,DP14:DR14,DU14:DW14,DZ14:EB14) -> 0 | BW14: =BU14*$H14+($I14+$J14)*BV14 -> 0 | CB14: =BZ14*$H14+($I14+$J14)*CA14 -> 0 | CG14: =CE14*$H14+($I14+$J14)*CF14 -> 0 | CL14: =CJ14*$H14+($I14+$J14)*CK14 -> 0 | CQ14: =CO14*$H14+($I14+$J14)*CP14 -> 0 | CV14: =CT14*$H14+($I14+$J14)*CU14 -> 0 | DA14: =CY14*$H14+($I14+$J14)*CZ14 -> 0 | DF14: =DD14*$H14+($I14+$J14)*DE14 -> 0 | DK14: =DI14*$H14+($I14+$J14)*DJ14 -> 0 | DP14: =DN14*$H14+($I14+$J14)*DO14 -> 0 | DU14: =DS14*$H14+($I14+$J14)*DT14 -> 0 | DZ14: =DX14*$H14+($I14+$J14)*DY14 -> 0 | EC14: =SUM(EF14:EH14,EK14:EM14,EP14:ER14,EU14:EW14,EZ14:FB14,FE14:FG14,FJ14:FL14,FO14:FQ14,FT14:FV14,FY14:GA14,GD14:GF14,GI14:GK14) -> 0 | EF14: =ED14*$H14+($I14+$J14)*EE14 -> 0 | EK14: =EI14*$H14+($I14+$J14)*EJ14 -> 0 | EP14: =EN14*$H14+($I14+$J14)*EO14 -> 0 | EU14: =ES14*$H14+($I14+$J14)*ET14 -> 0 | EZ14: =EX14*$H14+($I14+$J14)*EY14 -> 0 | FE14: =FC14*$H14+($I14+$J14)*FD14 -> 0 | FJ14: =FH14*$H14+($I14+$J14)*FI14 -> 0 | FO14: =FM14*$H14+($I14+$J14)*FN14 -> 0 | FT14: =FR14*$H14+($I14+$J14)*FS14 -> 0 | FY14: =FW14*$H14+($I14+$J14)*FX14 -> 0 | GD14: =GB14*$H14+($I14+$J14)*GC14 -> 0 | GI14: =GG14*$H14+($I14+$J14)*GH14 -> 0
A15: 12 | B15: =[1]项目立项!C35 -> 0 | C15: =[1]项目立项!D35 -> 0 | D15: =[1]项目立项!E35 -> 0 | E15: =[1]项目立项!F35 -> 0 | G15: =K15+BT15+EC15 -> 0 | K15: =SUM(N15:P15,S15:U15,X15:Z15,AC15:AE15,AH15:AJ15,AM15:AO15,AR15:AT15,AW15:AY15,BB15:BD15,BG15:BI15,BL15:BN15,BQ15:BS15) -> 0 | N15: =L15*$H15+($I15+$J15)*M15 -> 0 | S15: =Q15*$H15+($I15+$J15)*R15 -> 0 | X15: =V15*$H15+($I15+$J15)*W15 -> 0 | AC15: =AA15*$H15+($I15+$J15)*AB15 -> 0 | AH15: =AF15*$H15+($I15+$J15)*AG15 -> 0 | AM15: =AK15*$H15+($I15+$J15)*AL15 -> 0 | AR15: =AP15*$H15+($I15+$J15)*AQ15 -> 0 | AW15: =AU15*$H15+($I15+$J15)*AV15 -> 0 | BB15: =AZ15*$H15+($I15+$J15)*BA15 -> 0 | BG15: =BE15*$H15+($I15+$J15)*BF15 -> 0 | BL15: =BJ15*$H15+($I15+$J15)*BK15 -> 0 | BQ15: =BO15*$H15+($I15+$J15)*BP15 -> 0 | BT15: =SUM(BW15:BY15,CB15:CD15,CG15:CI15,CL15:CN15,CQ15:CS15,CV15:CX15,DA15:DC15,DF15:DH15,DK15:DM15,DP15:DR15,DU15:DW15,DZ15:EB15) -> 0 | BW15: =BU15*$H15+($I15+$J15)*BV15 -> 0 | CB15: =BZ15*$H15+($I15+$J15)*CA15 -> 0 | CG15: =CE15*$H15+($I15+$J15)*CF15 -> 0 | CL15: =CJ15*$H15+($I15+$J15)*CK15 -> 0 | CQ15: =CO15*$H15+($I15+$J15)*CP15 -> 0 | CV15: =CT15*$H15+($I15+$J15)*CU15 -> 0 | DA15: =CY15*$H15+($I15+$J15)*CZ15 -> 0 | DF15: =DD15*$H15+($I15+$J15)*DE15 -> 0 | DK15: =DI15*$H15+($I15+$J15)*DJ15 -> 0 | DP15: =DN15*$H15+($I15+$J15)*DO15 -> 0 | DU15: =DS15*$H15+($I15+$J15)*DT15 -> 0 | DZ15: =DX15*$H15+($I15+$J15)*DY15 -> 0 | EC15: =SUM(EF15:EH15,EK15:EM15,EP15:ER15,EU15:EW15,EZ15:FB15,FE15:FG15,FJ15:FL15,FO15:FQ15,FT15:FV15,FY15:GA15,GD15:GF15,GI15:GK15) -> 0 | EF15: =ED15*$H15+($I15+$J15)*EE15 -> 0 | EK15: =EI15*$H15+($I15+$J15)*EJ15 -> 0 | EP15: =EN15*$H15+($I15+$J15)*EO15 -> 0 | EU15: =ES15*$H15+($I15+$J15)*ET15 -> 0 | EZ15: =EX15*$H15+($I15+$J15)*EY15 -> 0 | FE15: =FC15*$H15+($I15+$J15)*FD15 -> 0 | FJ15: =FH15*$H15+($I15+$J15)*FI15 -> 0 | FO15: =FM15*$H15+($I15+$J15)*FN15 -> 0 | FT15: =FR15*$H15+($I15+$J15)*FS15 -> 0 | FY15: =FW15*$H15+($I15+$J15)*FX15 -> 0 | GD15: =GB15*$H15+($I15+$J15)*GC15 -> 0 | GI15: =GG15*$H15+($I15+$J15)*GH15 -> 0
... A43: 40 | B43: =[1]项目立项!C63 -> 0 | C43: =[1]项目立项!D63 -> 0 | D43: =[1]项目立项!E63 -> 0 | E43: =[1]项目立项!F63 -> 0 | G43: =K43+BT43+EC43 -> 0 | K43: =SUM(N43:P43,S43:U43,X43:Z43,AC43:AE43,AH43:AJ43,AM43:AO43,AR43:AT43,AW43:AY43,BB43:BD43,BG43:BI43,BL43:BN43,BQ43:BS43) -> 0 | N43: =L43*$H43+($I43+$J43)*M43 -> 0 | S43: =Q43*$H43+($I43+$J43)*R43 -> 0 | X43: =V43*$H43+($I43+$J43)*W43 -> 0 | AC43: =AA43*$H43+($I43+$J43)*AB43 -> 0 | AH43: =AF43*$H43+($I43+$J43)*AG43 -> 0 | AM43: =AK43*$H43+($I43+$J43)*AL43 -> 0 | AR43: =AP43*$H43+($I43+$J43)*AQ43 -> 0 | AW43: =AU43*$H43+($I43+$J43)*AV43 -> 0 | BB43: =AZ43*$H43+($I43+$J43)*BA43 -> 0 | BG43: =BE43*$H43+($I43+$J43)*BF43 -> 0 | BL43: =BJ43*$H43+($I43+$J43)*BK43 -> 0 | BQ43: =BO43*$H43+($I43+$J43)*BP43 -> 0 | BT43: =SUM(BW43:BY43,CB43:CD43,CG43:CI43,CL43:CN43,CQ43:CS43,CV43:CX43,DA43:DC43,DF43:DH43,DK43:DM43,DP43:DR43,DU43:DW43,DZ43:EB43) -> 0 | BW43: =BU43*$H43+($I43+$J43)*BV43 -> 0 | CB43: =BZ43*$H43+($I43+$J43)*CA43 -> 0 | CG43: =CE43*$H43+($I43+$J43)*CF43 -> 0 | CL43: =CJ43*$H43+($I43+$J43)*CK43 -> 0 | CQ43: =CO43*$H43+($I43+$J43)*CP43 -> 0 | CV43: =CT43*$H43+($I43+$J43)*CU43 -> 0 | DA43: =CY43*$H43+($I43+$J43)*CZ43 -> 0 | DF43: =DD43*$H43+($I43+$J43)*DE43 -> 0 | DK43: =DI43*$H43+($I43+$J43)*DJ43 -> 0 | DP43: =DN43*$H43+($I43+$J43)*DO43 -> 0 | DU43: =DS43*$H43+($I43+$J43)*DT43 -> 0 | DZ43: =DX43*$H43+($I43+$J43)*DY43 -> 0 | EC43: =SUM(EF43:EH43,EK43:EM43,EP43:ER43,EU43:EW43,EZ43:FB43,FE43:FG43,FJ43:FL43,FO43:FQ43,FT43:FV43,FY43:GA43,GD43:GF43,GI43:GK43) -> 0 | EF43: =ED43*$H43+($I43+$J43)*EE43 -> 0 | EK43: =EI43*$H43+($I43+$J43)*EJ43 -> 0 | EP43: =EN43*$H43+($I43+$J43)*EO43 -> 0 | EU43: =ES43*$H43+($I43+$J43)*ET43 -> 0 | EZ43: =EX43*$H43+($I43+$J43)*EY43 -> 0 | FE43: =FC43*$H43+($I43+$J43)*FD43 -> 0 | FJ43: =FH43*$H43+($I43+$J43)*FI43 -> 0 | FO43: =FM43*$H43+($I43+$J43)*FN43 -> 0 | FT43: =FR43*$H43+($I43+$J43)*FS43 -> 0 | FY43: =FW43*$H43+($I43+$J43)*FX43 -> 0 | GD43: =GB43*$H43+($I43+$J43)*GC43 -> 0 | GI43: =GG43*$H43+($I43+$J43)*GH43 -> 0
A44: 合计 | K44: =SUM(K4:K43) -> 0 | L44: =SUM(L4:L43) -> 0 | M44: =SUM(M4:M43) -> 0 | N44: =SUM(N4:N43) -> 0 | O44: =SUM(O4:O43) -> 0 | P44: =SUM(P4:P43) -> 0 | Q44: =SUM(Q4:Q43) -> 0 | R44: =SUM(R4:R43) -> 0 | ... EC44: =SUM(EC4:EC43) -> 0
